[2025-10-30T17:05:14.838+0000] {local_task_job_runner.py:120} INFO - ::group::Pre task execution logs
[2025-10-30T17:05:14.871+0000] {taskinstance.py:2076} INFO - Dependencies all met for dep_context=non-requeueable deps ti=<TaskInstance: api_to_postgres_dag.transform_data manual__2025-10-30T17:05:12.664337+00:00 [queued]>
[2025-10-30T17:05:14.881+0000] {taskinstance.py:2076} INFO - Dependencies all met for dep_context=requeueable deps ti=<TaskInstance: api_to_postgres_dag.transform_data manual__2025-10-30T17:05:12.664337+00:00 [queued]>
[2025-10-30T17:05:14.882+0000] {taskinstance.py:2306} INFO - Starting attempt 1 of 3
[2025-10-30T17:05:14.895+0000] {taskinstance.py:2330} INFO - Executing <Task(PythonOperator): transform_data> on 2025-10-30 17:05:12.664337+00:00
[2025-10-30T17:05:14.902+0000] {standard_task_runner.py:63} INFO - Started process 417 to run task
[2025-10-30T17:05:14.905+0000] {standard_task_runner.py:90} INFO - Running: ['***', 'tasks', 'run', 'api_to_postgres_dag', 'transform_data', 'manual__2025-10-30T17:05:12.664337+00:00', '--job-id', '6', '--raw', '--subdir', 'DAGS_FOLDER/api_to_postgres_dag.py', '--cfg-path', '/tmp/tmp_k70i_dh']
[2025-10-30T17:05:14.907+0000] {standard_task_runner.py:91} INFO - Job 6: Subtask transform_data
[2025-10-30T17:05:14.961+0000] {task_command.py:426} INFO - Running <TaskInstance: api_to_postgres_dag.transform_data manual__2025-10-30T17:05:12.664337+00:00 [running]> on host eeda63f307c4
[2025-10-30T17:05:15.048+0000] {taskinstance.py:2648} INFO - Exporting env vars: AIRFLOW_CTX_DAG_OWNER='lenny' AIRFLOW_CTX_DAG_ID='api_to_postgres_dag' AIRFLOW_CTX_TASK_ID='transform_data' AIRFLOW_CTX_EXECUTION_DATE='2025-10-30T17:05:12.664337+00:00' AIRFLOW_CTX_TRY_NUMBER='1' AIRFLOW_CTX_DAG_RUN_ID='manual__2025-10-30T17:05:12.664337+00:00'
[2025-10-30T17:05:15.050+0000] {taskinstance.py:430} INFO - ::endgroup::
[2025-10-30T17:05:15.066+0000] {taskinstance.py:441} INFO - ::group::Post task execution logs
[2025-10-30T17:05:15.067+0000] {taskinstance.py:2905} ERROR - Task failed with exception
Traceback (most recent call last):
  File "/home/airflow/.local/lib/python3.11/site-packages/airflow/models/taskinstance.py", line 465, in _execute_task
    result = _execute_callable(context=context, **execute_callable_kwargs)
             ^^^^^^^^^^^^^^^^^^^^^^^^^^^^^^^^^^^^^^^^^^^^^^^^^^^^^^^^^^^^^
  File "/home/airflow/.local/lib/python3.11/site-packages/airflow/models/taskinstance.py", line 432, in _execute_callable
    return execute_callable(context=context, **execute_callable_kwargs)
           ^^^^^^^^^^^^^^^^^^^^^^^^^^^^^^^^^^^^^^^^^^^^^^^^^^^^^^^^^^^^
  File "/home/airflow/.local/lib/python3.11/site-packages/airflow/models/baseoperator.py", line 401, in wrapper
    return func(self, *args, **kwargs)
           ^^^^^^^^^^^^^^^^^^^^^^^^^^^
  File "/home/airflow/.local/lib/python3.11/site-packages/airflow/operators/python.py", line 235, in execute
    return_value = self.execute_callable()
                   ^^^^^^^^^^^^^^^^^^^^^^^
  File "/home/airflow/.local/lib/python3.11/site-packages/airflow/operators/python.py", line 252, in execute_callable
    return self.python_callable(*self.op_args, **self.op_kwargs)
           ^^^^^^^^^^^^^^^^^^^^^^^^^^^^^^^^^^^^^^^^^^^^^^^^^^^^^
  File "/opt/airflow/dags/api_to_postgres_dag.py", line 54, in transform_data
    df = df[["name", "email", "address.city"]].rename(columns={"address.city": "city"})
         ~~^^^^^^^^^^^^^^^^^^^^^^^^^^^^^^^^^^^
  File "/home/airflow/.local/lib/python3.11/site-packages/pandas/core/frame.py", line 3899, in __getitem__
    indexer = self.columns._get_indexer_strict(key, "columns")[1]
              ^^^^^^^^^^^^^^^^^^^^^^^^^^^^^^^^^^^^^^^^^^^^^^^^
  File "/home/airflow/.local/lib/python3.11/site-packages/pandas/core/indexes/base.py", line 6115, in _get_indexer_strict
    self._raise_if_missing(keyarr, indexer, axis_name)
  File "/home/airflow/.local/lib/python3.11/site-packages/pandas/core/indexes/base.py", line 6179, in _raise_if_missing
    raise KeyError(f"{not_found} not in index")
KeyError: "['address.city'] not in index"
[2025-10-30T17:05:15.087+0000] {taskinstance.py:1206} INFO - Marking task as UP_FOR_RETRY. dag_id=api_to_postgres_dag, task_id=transform_data, run_id=manual__2025-10-30T17:05:12.664337+00:00, execution_date=20251030T170512, start_date=20251030T170514, end_date=20251030T170515
[2025-10-30T17:05:15.100+0000] {standard_task_runner.py:110} ERROR - Failed to execute job 6 for task transform_data ("['address.city'] not in index"; 417)
[2025-10-30T17:05:15.119+0000] {local_task_job_runner.py:240} INFO - Task exited with return code 1
[2025-10-30T17:05:15.144+0000] {taskinstance.py:3503} INFO - 0 downstream tasks scheduled from follow-on schedule check
[2025-10-30T17:05:15.147+0000] {local_task_job_runner.py:222} INFO - ::endgroup::
