[2025-10-30T17:10:03.883+0000] {local_task_job_runner.py:120} INFO - ::group::Pre task execution logs
[2025-10-30T17:10:03.918+0000] {taskinstance.py:2076} INFO - Dependencies all met for dep_context=non-requeueable deps ti=<TaskInstance: api_to_postgres_dag.transform_data scheduled__2025-10-29T00:00:00+00:00 [queued]>
[2025-10-30T17:10:03.930+0000] {taskinstance.py:2076} INFO - Dependencies all met for dep_context=requeueable deps ti=<TaskInstance: api_to_postgres_dag.transform_data scheduled__2025-10-29T00:00:00+00:00 [queued]>
[2025-10-30T17:10:03.931+0000] {taskinstance.py:2306} INFO - Starting attempt 2 of 3
[2025-10-30T17:10:03.944+0000] {taskinstance.py:2330} INFO - Executing <Task(PythonOperator): transform_data> on 2025-10-29 00:00:00+00:00
[2025-10-30T17:10:03.951+0000] {standard_task_runner.py:63} INFO - Started process 492 to run task
[2025-10-30T17:10:03.954+0000] {standard_task_runner.py:90} INFO - Running: ['***', 'tasks', 'run', 'api_to_postgres_dag', 'transform_data', 'scheduled__2025-10-29T00:00:00+00:00', '--job-id', '11', '--raw', '--subdir', 'DAGS_FOLDER/api_to_postgres_dag.py', '--cfg-path', '/tmp/tmpzs7lknpf']
[2025-10-30T17:10:03.957+0000] {standard_task_runner.py:91} INFO - Job 11: Subtask transform_data
[2025-10-30T17:10:04.032+0000] {task_command.py:426} INFO - Running <TaskInstance: api_to_postgres_dag.transform_data scheduled__2025-10-29T00:00:00+00:00 [running]> on host eeda63f307c4
[2025-10-30T17:10:04.142+0000] {taskinstance.py:2648} INFO - Exporting env vars: AIRFLOW_CTX_DAG_OWNER='lenny' AIRFLOW_CTX_DAG_ID='api_to_postgres_dag' AIRFLOW_CTX_TASK_ID='transform_data' AIRFLOW_CTX_EXECUTION_DATE='2025-10-29T00:00:00+00:00' AIRFLOW_CTX_TRY_NUMBER='2' AIRFLOW_CTX_DAG_RUN_ID='scheduled__2025-10-29T00:00:00+00:00'
[2025-10-30T17:10:04.145+0000] {taskinstance.py:430} INFO - ::endgroup::
[2025-10-30T17:10:04.168+0000] {taskinstance.py:441} INFO - ::group::Post task execution logs
[2025-10-30T17:10:04.169+0000] {taskinstance.py:2905} ERROR - Task failed with exception
Traceback (most recent call last):
  File "/home/airflow/.local/lib/python3.11/site-packages/airflow/models/taskinstance.py", line 465, in _execute_task
    result = _execute_callable(context=context, **execute_callable_kwargs)
             ^^^^^^^^^^^^^^^^^^^^^^^^^^^^^^^^^^^^^^^^^^^^^^^^^^^^^^^^^^^^^
  File "/home/airflow/.local/lib/python3.11/site-packages/airflow/models/taskinstance.py", line 432, in _execute_callable
    return execute_callable(context=context, **execute_callable_kwargs)
           ^^^^^^^^^^^^^^^^^^^^^^^^^^^^^^^^^^^^^^^^^^^^^^^^^^^^^^^^^^^^
  File "/home/airflow/.local/lib/python3.11/site-packages/airflow/models/baseoperator.py", line 401, in wrapper
    return func(self, *args, **kwargs)
           ^^^^^^^^^^^^^^^^^^^^^^^^^^^
  File "/home/airflow/.local/lib/python3.11/site-packages/airflow/operators/python.py", line 235, in execute
    return_value = self.execute_callable()
                   ^^^^^^^^^^^^^^^^^^^^^^^
  File "/home/airflow/.local/lib/python3.11/site-packages/airflow/operators/python.py", line 252, in execute_callable
    return self.python_callable(*self.op_args, **self.op_kwargs)
           ^^^^^^^^^^^^^^^^^^^^^^^^^^^^^^^^^^^^^^^^^^^^^^^^^^^^^
  File "/opt/airflow/dags/api_to_postgres_dag.py", line 54, in transform_data
    df = df[["name", "email", "address.city"]].rename(columns={"address.city": "city"})
         ~~^^^^^^^^^^^^^^^^^^^^^^^^^^^^^^^^^^^
  File "/home/airflow/.local/lib/python3.11/site-packages/pandas/core/frame.py", line 3899, in __getitem__
    indexer = self.columns._get_indexer_strict(key, "columns")[1]
              ^^^^^^^^^^^^^^^^^^^^^^^^^^^^^^^^^^^^^^^^^^^^^^^^
  File "/home/airflow/.local/lib/python3.11/site-packages/pandas/core/indexes/base.py", line 6115, in _get_indexer_strict
    self._raise_if_missing(keyarr, indexer, axis_name)
  File "/home/airflow/.local/lib/python3.11/site-packages/pandas/core/indexes/base.py", line 6179, in _raise_if_missing
    raise KeyError(f"{not_found} not in index")
KeyError: "['address.city'] not in index"
[2025-10-30T17:10:04.191+0000] {taskinstance.py:1206} INFO - Marking task as UP_FOR_RETRY. dag_id=api_to_postgres_dag, task_id=transform_data, run_id=scheduled__2025-10-29T00:00:00+00:00, execution_date=20251029T000000, start_date=20251030T171003, end_date=20251030T171004
[2025-10-30T17:10:04.203+0000] {standard_task_runner.py:110} ERROR - Failed to execute job 11 for task transform_data ("['address.city'] not in index"; 492)
[2025-10-30T17:10:04.250+0000] {local_task_job_runner.py:240} INFO - Task exited with return code 1
[2025-10-30T17:10:04.278+0000] {taskinstance.py:3503} INFO - 0 downstream tasks scheduled from follow-on schedule check
[2025-10-30T17:10:04.281+0000] {local_task_job_runner.py:222} INFO - ::endgroup::
