[2025-10-31T02:39:15.988+0000] {local_task_job_runner.py:120} INFO - ::group::Pre task execution logs
[2025-10-31T02:39:16.021+0000] {taskinstance.py:2076} INFO - Dependencies all met for dep_context=non-requeueable deps ti=<TaskInstance: api_to_postgres_dag.transform_data manual__2025-10-31T02:29:09.958149+00:00 [queued]>
[2025-10-31T02:39:16.030+0000] {taskinstance.py:2076} INFO - Dependencies all met for dep_context=requeueable deps ti=<TaskInstance: api_to_postgres_dag.transform_data manual__2025-10-31T02:29:09.958149+00:00 [queued]>
[2025-10-31T02:39:16.031+0000] {taskinstance.py:2306} INFO - Starting attempt 3 of 3
[2025-10-31T02:39:16.044+0000] {taskinstance.py:2330} INFO - Executing <Task(PythonOperator): transform_data> on 2025-10-31 02:29:09.958149+00:00
[2025-10-31T02:39:16.050+0000] {standard_task_runner.py:63} INFO - Started process 807 to run task
[2025-10-31T02:39:16.053+0000] {standard_task_runner.py:90} INFO - Running: ['***', 'tasks', 'run', 'api_to_postgres_dag', 'transform_data', 'manual__2025-10-31T02:29:09.958149+00:00', '--job-id', '43', '--raw', '--subdir', 'DAGS_FOLDER/api_to_postgres_dag.py', '--cfg-path', '/tmp/tmp118o6ppi']
[2025-10-31T02:39:16.056+0000] {standard_task_runner.py:91} INFO - Job 43: Subtask transform_data
[2025-10-31T02:39:16.118+0000] {task_command.py:426} INFO - Running <TaskInstance: api_to_postgres_dag.transform_data manual__2025-10-31T02:29:09.958149+00:00 [running]> on host 754154eb0275
[2025-10-31T02:39:16.214+0000] {taskinstance.py:2648} INFO - Exporting env vars: AIRFLOW_CTX_DAG_OWNER='lenny' AIRFLOW_CTX_DAG_ID='api_to_postgres_dag' AIRFLOW_CTX_TASK_ID='transform_data' AIRFLOW_CTX_EXECUTION_DATE='2025-10-31T02:29:09.958149+00:00' AIRFLOW_CTX_TRY_NUMBER='3' AIRFLOW_CTX_DAG_RUN_ID='manual__2025-10-31T02:29:09.958149+00:00'
[2025-10-31T02:39:16.216+0000] {taskinstance.py:430} INFO - ::endgroup::
[2025-10-31T02:39:16.234+0000] {taskinstance.py:441} INFO - ::group::Post task execution logs
[2025-10-31T02:39:16.235+0000] {taskinstance.py:2905} ERROR - Task failed with exception
Traceback (most recent call last):
  File "/home/airflow/.local/lib/python3.11/site-packages/airflow/models/taskinstance.py", line 465, in _execute_task
    result = _execute_callable(context=context, **execute_callable_kwargs)
             ^^^^^^^^^^^^^^^^^^^^^^^^^^^^^^^^^^^^^^^^^^^^^^^^^^^^^^^^^^^^^
  File "/home/airflow/.local/lib/python3.11/site-packages/airflow/models/taskinstance.py", line 432, in _execute_callable
    return execute_callable(context=context, **execute_callable_kwargs)
           ^^^^^^^^^^^^^^^^^^^^^^^^^^^^^^^^^^^^^^^^^^^^^^^^^^^^^^^^^^^^
  File "/home/airflow/.local/lib/python3.11/site-packages/airflow/models/baseoperator.py", line 401, in wrapper
    return func(self, *args, **kwargs)
           ^^^^^^^^^^^^^^^^^^^^^^^^^^^
  File "/home/airflow/.local/lib/python3.11/site-packages/airflow/operators/python.py", line 235, in execute
    return_value = self.execute_callable()
                   ^^^^^^^^^^^^^^^^^^^^^^^
  File "/home/airflow/.local/lib/python3.11/site-packages/airflow/operators/python.py", line 252, in execute_callable
    return self.python_callable(*self.op_args, **self.op_kwargs)
           ^^^^^^^^^^^^^^^^^^^^^^^^^^^^^^^^^^^^^^^^^^^^^^^^^^^^^
  File "/opt/airflow/dags/api_to_postgres_dag.py", line 54, in transform_data
    df = df[["name", "email", "address.city"]].rename(columns={"address.city": "city"})
         ~~^^^^^^^^^^^^^^^^^^^^^^^^^^^^^^^^^^^
  File "/home/airflow/.local/lib/python3.11/site-packages/pandas/core/frame.py", line 3899, in __getitem__
    indexer = self.columns._get_indexer_strict(key, "columns")[1]
              ^^^^^^^^^^^^^^^^^^^^^^^^^^^^^^^^^^^^^^^^^^^^^^^^
  File "/home/airflow/.local/lib/python3.11/site-packages/pandas/core/indexes/base.py", line 6115, in _get_indexer_strict
    self._raise_if_missing(keyarr, indexer, axis_name)
  File "/home/airflow/.local/lib/python3.11/site-packages/pandas/core/indexes/base.py", line 6179, in _raise_if_missing
    raise KeyError(f"{not_found} not in index")
KeyError: "['address.city'] not in index"
[2025-10-31T02:39:16.254+0000] {taskinstance.py:1206} INFO - Marking task as FAILED. dag_id=api_to_postgres_dag, task_id=transform_data, run_id=manual__2025-10-31T02:29:09.958149+00:00, execution_date=20251031T022909, start_date=20251031T023916, end_date=20251031T023916
[2025-10-31T02:39:16.266+0000] {standard_task_runner.py:110} ERROR - Failed to execute job 43 for task transform_data ("['address.city'] not in index"; 807)
[2025-10-31T02:39:16.307+0000] {local_task_job_runner.py:240} INFO - Task exited with return code 1
[2025-10-31T02:39:16.331+0000] {taskinstance.py:3503} INFO - 0 downstream tasks scheduled from follow-on schedule check
[2025-10-31T02:39:16.336+0000] {local_task_job_runner.py:222} INFO - ::endgroup::
