[2025-10-31T02:47:00.765+0000] {local_task_job_runner.py:120} INFO - ::group::Pre task execution logs
[2025-10-31T02:47:00.796+0000] {taskinstance.py:2076} INFO - Dependencies all met for dep_context=non-requeueable deps ti=<TaskInstance: api_to_postgres_dag.load_to_postgres manual__2025-10-31T02:32:27.281802+00:00 [queued]>
[2025-10-31T02:47:00.805+0000] {taskinstance.py:2076} INFO - Dependencies all met for dep_context=requeueable deps ti=<TaskInstance: api_to_postgres_dag.load_to_postgres manual__2025-10-31T02:32:27.281802+00:00 [queued]>
[2025-10-31T02:47:00.806+0000] {taskinstance.py:2306} INFO - Starting attempt 1 of 3
[2025-10-31T02:47:00.820+0000] {taskinstance.py:2330} INFO - Executing <Task(PythonOperator): load_to_postgres> on 2025-10-31 02:32:27.281802+00:00
[2025-10-31T02:47:00.826+0000] {standard_task_runner.py:63} INFO - Started process 260 to run task
[2025-10-31T02:47:00.828+0000] {standard_task_runner.py:90} INFO - Running: ['***', 'tasks', 'run', 'api_to_postgres_dag', 'load_to_postgres', 'manual__2025-10-31T02:32:27.281802+00:00', '--job-id', '60', '--raw', '--subdir', 'DAGS_FOLDER/api_to_postgres_dag.py', '--cfg-path', '/tmp/tmp4bvj5_15']
[2025-10-31T02:47:00.831+0000] {standard_task_runner.py:91} INFO - Job 60: Subtask load_to_postgres
[2025-10-31T02:47:00.891+0000] {task_command.py:426} INFO - Running <TaskInstance: api_to_postgres_dag.load_to_postgres manual__2025-10-31T02:32:27.281802+00:00 [running]> on host 754154eb0275
[2025-10-31T02:47:00.982+0000] {taskinstance.py:2648} INFO - Exporting env vars: AIRFLOW_CTX_DAG_OWNER='lenny' AIRFLOW_CTX_DAG_ID='api_to_postgres_dag' AIRFLOW_CTX_TASK_ID='load_to_postgres' AIRFLOW_CTX_EXECUTION_DATE='2025-10-31T02:32:27.281802+00:00' AIRFLOW_CTX_TRY_NUMBER='1' AIRFLOW_CTX_DAG_RUN_ID='manual__2025-10-31T02:32:27.281802+00:00'
[2025-10-31T02:47:00.983+0000] {taskinstance.py:430} INFO - ::endgroup::
[2025-10-31T02:47:01.005+0000] {taskinstance.py:441} INFO - ::group::Post task execution logs
[2025-10-31T02:47:01.005+0000] {taskinstance.py:2905} ERROR - Task failed with exception
Traceback (most recent call last):
  File "/home/airflow/.local/lib/python3.11/site-packages/airflow/models/taskinstance.py", line 465, in _execute_task
    result = _execute_callable(context=context, **execute_callable_kwargs)
             ^^^^^^^^^^^^^^^^^^^^^^^^^^^^^^^^^^^^^^^^^^^^^^^^^^^^^^^^^^^^^
  File "/home/airflow/.local/lib/python3.11/site-packages/airflow/models/taskinstance.py", line 432, in _execute_callable
    return execute_callable(context=context, **execute_callable_kwargs)
           ^^^^^^^^^^^^^^^^^^^^^^^^^^^^^^^^^^^^^^^^^^^^^^^^^^^^^^^^^^^^
  File "/home/airflow/.local/lib/python3.11/site-packages/airflow/models/baseoperator.py", line 401, in wrapper
    return func(self, *args, **kwargs)
           ^^^^^^^^^^^^^^^^^^^^^^^^^^^
  File "/home/airflow/.local/lib/python3.11/site-packages/airflow/operators/python.py", line 235, in execute
    return_value = self.execute_callable()
                   ^^^^^^^^^^^^^^^^^^^^^^^
  File "/home/airflow/.local/lib/python3.11/site-packages/airflow/operators/python.py", line 252, in execute_callable
    return self.python_callable(*self.op_args, **self.op_kwargs)
           ^^^^^^^^^^^^^^^^^^^^^^^^^^^^^^^^^^^^^^^^^^^^^^^^^^^^^
  File "/opt/airflow/dags/api_to_postgres_dag.py", line 70, in load_data
    conn = psycopg2.connect(
           ^^^^^^^^^^^^^^^^^
  File "/home/airflow/.local/lib/python3.11/site-packages/psycopg2/__init__.py", line 122, in connect
    conn = _connect(dsn, connection_factory=connection_factory, **kwasync)
           ^^^^^^^^^^^^^^^^^^^^^^^^^^^^^^^^^^^^^^^^^^^^^^^^^^^^^^^^^^^^^^^
psycopg2.OperationalError: connection to server at "localhost" (::1), port 5432 failed: Connection refused
	Is the server running on that host and accepting TCP/IP connections?
connection to server at "localhost" (127.0.0.1), port 5432 failed: Connection refused
	Is the server running on that host and accepting TCP/IP connections?

[2025-10-31T02:47:01.020+0000] {taskinstance.py:1206} INFO - Marking task as UP_FOR_RETRY. dag_id=api_to_postgres_dag, task_id=load_to_postgres, run_id=manual__2025-10-31T02:32:27.281802+00:00, execution_date=20251031T023227, start_date=20251031T024700, end_date=20251031T024701
[2025-10-31T02:47:01.034+0000] {standard_task_runner.py:110} ERROR - Failed to execute job 60 for task load_to_postgres (connection to server at "localhost" (::1), port 5432 failed: Connection refused
	Is the server running on that host and accepting TCP/IP connections?
connection to server at "localhost" (127.0.0.1), port 5432 failed: Connection refused
	Is the server running on that host and accepting TCP/IP connections?
; 260)
[2025-10-31T02:47:01.082+0000] {local_task_job_runner.py:240} INFO - Task exited with return code 1
[2025-10-31T02:47:01.100+0000] {taskinstance.py:3503} INFO - 0 downstream tasks scheduled from follow-on schedule check
[2025-10-31T02:47:01.102+0000] {local_task_job_runner.py:222} INFO - ::endgroup::
